<?xml version="1.0"?>
<robot name="gaze_arm">
  <link name="base_link">
    <visual>
      <origin xyz="0 0 0.044" rpy="0 0 0" />
      <geometry>
        <cylinder radius="0.015" length="0.088" />
      </geometry>
      <material name="blue">
        <color rgba="0 0 .8 1" />
      </material>
    </visual>

    <collision>
      <origin xyz="0 0 0.044" rpy="0 0 0" />
      <geometry>
        <cylinder radius="0.015" length="0.088" />
      </geometry>
    </collision>

    <inertial>
      <origin xyz="0 0 0.044" rpy="0 0 0" />
      <mass value="0.03" />
      <inertia ixx="1.0" ixy="0.0" ixz="0.0"
                         iyy="1.0" iyz="0.0"
                                   izz="1.0" />
    </inertial>
  </link>

  <joint name="joint0" type="fixed">
    <parent link="base_link"/>
    <child link="link1"/>
    <origin xyz="0 0 0.088" rpy="0 0.523594667 0" />
    <axis xyz="0 1 0" />
  </joint>

  <link name="link1">
    <visual>
      <origin xyz="0 0 0.035" rpy="0 0 0" />
      <geometry>
        <cylinder radius="0.01" length="0.065" />
      </geometry>
      <material name="blue" />
    </visual>

    <collision>
      <origin xyz="0 0 0.035" rpy="0 0 0" />
      <geometry>
        <cylinder radius="0.01" length="0.065" />
      </geometry>
    </collision>

    <inertial>
      <origin xyz="0 0 0.035" rpy="0 0 0" />
      <mass value="0.03" />
      <inertia ixx="1.0" ixy="0.0" ixz="0.0"
                         iyy="1.0" iyz="0.0"
                                   izz="1.0" />
    </inertial>
  </link>

  <joint name="joint1" type="revolute">
    <parent link="link1"/>
    <child link="link2"/>
    <origin xyz="0 0 0.086" rpy="0 0 0" />
    <axis xyz="0 1 0" />
    <limit lower="-1.57" upper="1.57" effort="0.5293" velocity="6.159937255" />
    <dynamics damping="0.4" />
  </joint>

  <link name="link2">
    <visual>
      <origin xyz="0 0 0.005" rpy="0 0 0" />
      <geometry>
        <box size="0.015 0.045 0.05" />
      </geometry>
      <material name="green">
        <color rgba="0 .8 0 1" />
      </material>
    </visual>

    <collision>
      <origin xyz="0 0 0.005" rpy="0 0 0" />
      <geometry>
        <box size="0.015 0.045 0.035" />
      </geometry>
    </collision>

    <inertial>
      <origin xyz="0 0 0.005" />
      <mass value="0.04" />
      <inertia ixx="1.0" ixy="0.0" ixz="0.0"
                         iyy="1.0" iyz="0.0"
                                   izz="1.0" />
    </inertial>
  </link>

  <joint name="joint2" type="revolute">
    <parent link="link2"/>
    <child link="link3"/>
    <origin xyz="0 0 0.06" rpy="0 0 0" />
    <axis xyz="1 0 0" />
    <limit lower="-1.046666667" upper="1.046666667" effort="0.5293" velocity="6.159937255" />
    <dynamics damping="0.4" />
  </joint>

  <link name="link3">
    <visual>
      <origin xyz="0 0 -0.005" rpy="0 0 0" />
      <geometry>
        <box size="0.045 0.015 0.05" />
      </geometry>
      <material name="orange">
        <color rgba="1 .64 0 1" />
      </material>
    </visual>

    <collision>
      <origin xyz="0 0 -0.005" rpy="0 0 0" />
      <geometry>
        <box size="0.045 0.015 0.05" />
      </geometry>
    </collision>

    <inertial>
      <origin xyz="0 0 -0.005" rpy="0 0 0" />
      <mass value="0.04" />
      <inertia ixx="1.0" ixy="0.0" ixz="0.0"
                         iyy="1.0" iyz="0.0"
                                   izz="1.0" />
    </inertial>
  </link>


  <joint name="camera_joint" type="fixed">
    <parent link="link3"/>
    <child link="camera_link"/>
    <origin xyz="0.015 0 0.025" rpy="0 0 0" />
  </joint>

  <link name="camera_link">
    <visual>
      <origin xyz="0 0 0.0125" rpy="0 0 0" />
      <geometry>
        <box size="0.05 0.045 0.025" />
      </geometry>
      <material name="red">
        <color rgba=".8 0 0 1" />
      </material>
    </visual>

    <collision>
      <origin xyz="0 0 0.0125" rpy="0 0 0" />
      <geometry>
        <box size="0.05 0.045 0.025" />
      </geometry>
    </collision>

    <inertial>
      <origin xyz="0 0 0.0125" rpy="0 0 0" />
      <mass value="0.04" />
      <inertia ixx="1.0" ixy="0.0" ixz="0.0"
                         iyy="1.0" iyz="0.0"
                                   izz="1.0" />
    </inertial>
  </link>

</robot>
